Workbook

Sheet الملخص السنوي
A1: SocialEarth – الملخص المالي لثلاث سنوات
B3: السيناريو المعروض: | C3: =الافتراضات!C4 -> أساسي | D3: ← غيّره من ورقة الافتراضات (الخلية C4)
C4: نوف 26 – أكت 27 | D4: نوف 27 – أكت 28 | E4: نوف 28 – أكت 29
B5: البند | C5: السنة 1 | D5: السنة 2 | E5: السنة 3 | F5: الإجمالي
B6: المستخدمون
B7: المستخدمون النشطون آخر السنة (MAU) | C7: =INDEX('النموذج الشهري'!$C$13:$AL$13,1,C$50*12) -> 8854.226 | D7: =INDEX('النموذج الشهري'!$C$13:$AL$13,1,D$50*12) -> 41991.176 | E7: =INDEX('النموذج الشهري'!$C$13:$AL$13,1,E$50*12) -> 128275.61
B8: التحميلات الجديدة خلال السنة | C8: =SUMIF('النموذج الشهري'!$C$5:$AL$5,"السنة "&C$50,'النموذج الشهري'!$C$12:$AL$12) -> 29967.857 | D8: =SUMIF('النموذج الشهري'!$C$5:$AL$5,"السنة "&D$50,'النموذج الشهري'!$C$12:$AL$12) -> 156712.39 | E8: =SUMIF('النموذج الشهري'!$C$5:$AL$5,"السنة "&E$50,'النموذج الشهري'!$C$12:$AL$12) -> 482639.33 | F8: =SUM(C8:E8) -> 669319.58
B9: الأرباح والخسائر
B10: مشتريات داخل التطبيق | C10: =SUMIF('النموذج الشهري'!$C$5:$AL$5,"السنة "&C$50,'النموذج الشهري'!$C$17:$AL$17) -> 5857.1556 | D10: =SUMIF('النموذج الشهري'!$C$5:$AL$5,"السنة "&D$50,'النموذج الشهري'!$C$17:$AL$17) -> 60908.352 | E10: =SUMIF('النموذج الشهري'!$C$5:$AL$5,"السنة "&E$50,'النموذج الشهري'!$C$17:$AL$17) -> 223855.22 | F10: =SUM(C10:E10) -> 290620.73
B11: المحلات الممولة | C11: =SUMIF('النموذج الشهري'!$C$5:$AL$5,"السنة "&C$50,'النموذج الشهري'!$C$19:$AL$19) -> 1344.4267 | D11: =SUMIF('النموذج الشهري'!$C$5:$AL$5,"السنة "&D$50,'النموذج الشهري'!$C$19:$AL$19) -> 18272.506 | E11: =SUMIF('النموذج الشهري'!$C$5:$AL$5,"السنة "&E$50,'النموذج الشهري'!$C$19:$AL$19) -> 67156.566 | F11: =SUM(C11:E11) -> 86773.498
B12: الفعاليات والعلامات التجارية | C12: =SUMIF('النموذج الشهري'!$C$5:$AL$5,"السنة "&C$50,'النموذج الشهري'!$C$20:$AL$20) -> 585.71556 | D12: =SUMIF('النموذج الشهري'!$C$5:$AL$5,"السنة "&D$50,'النموذج الشهري'!$C$20:$AL$20) -> 6090.8352 | E12: =SUMIF('النموذج الشهري'!$C$5:$AL$5,"السنة "&E$50,'النموذج الشهري'!$C$20:$AL$20) -> 22385.522 | F12: =SUM(C12:E12) -> 29062.073
B13: إجمالي الإيرادات | C13: =SUMIF('النموذج الشهري'!$C$5:$AL$5,"السنة "&C$50,'النموذج الشهري'!$C$21:$AL$21) -> 7787.2978 | D13: =SUMIF('النموذج الشهري'!$C$5:$AL$5,"السنة "&D$50,'النموذج الشهري'!$C$21:$AL$21) -> 85271.693 | E13: =SUMIF('النموذج الشهري'!$C$5:$AL$5,"السنة "&E$50,'النموذج الشهري'!$C$21:$AL$21) -> 313397.31 | F13: =SUM(C13:E13) -> 406456.3
B14: تكلفة الإيرادات | C14: =SUMIF('النموذج الشهري'!$C$5:$AL$5,"السنة "&C$50,'النموذج الشهري'!$C$27:$AL$27) -> 6528.5778 | D14: =SUMIF('النموذج الشهري'!$C$5:$AL$5,"السنة "&D$50,'النموذج الشهري'!$C$27:$AL$27) -> 34054.176 | E14: =SUMIF('النموذج الشهري'!$C$5:$AL$5,"السنة "&E$50,'النموذج الشهري'!$C$27:$AL$27) -> 115527.61 | F14: =SUM(C14:E14) -> 156110.36
B15: إجمالي الربح | C15: =SUMIF('النموذج الشهري'!$C$5:$AL$5,"السنة "&C$50,'النموذج الشهري'!$C$28:$AL$28) -> 1258.72 | D15: =SUMIF('النموذج الشهري'!$C$5:$AL$5,"السنة "&D$50,'النموذج الشهري'!$C$28:$AL$28) -> 51217.517 | E15: =SUMIF('النموذج الشهري'!$C$5:$AL$5,"السنة "&E$50,'النموذج الشهري'!$C$28:$AL$28) -> 197869.7 | F15: =SUM(C15:E15) -> 250345.93
B16: الرواتب | C16: =SUMIF('النموذج الشهري'!$C$5:$AL$5,"السنة "&C$50,'النموذج الشهري'!$C$32:$AL$32) -> 147800 | D16: =SUMIF('النموذج الشهري'!$C$5:$AL$5,"السنة "&D$50,'النموذج الشهري'!$C$32:$AL$32) -> 422100 | E16: =SUMIF('النموذج الشهري'!$C$5:$AL$5,"السنة "&E$50,'النموذج الشهري'!$C$32:$AL$32) -> 694575 | F16: =SUM(C16:E16) -> 1264475
B17: التسويق | C17: =SUMIF('النموذج الشهري'!$C$5:$AL$5,"السنة "&C$50,'النموذج الشهري'!$C$33:$AL$33) -> 44600 | D17: =SUMIF('النموذج الشهري'!$C$5:$AL$5,"السنة "&D$50,'النموذج الشهري'!$C$33:$AL$33) -> 202500 | E17: =SUMIF('النموذج الشهري'!$C$5:$AL$5,"السنة "&E$50,'النموذج الشهري'!$C$33:$AL$33) -> 600000 | F17: =SUM(C17:E17) -> 847100
B18: أدوات وإدارية ولمرة واحدة وطوارئ | C18: =SUMIF('النموذج الشهري'!$C$5:$AL$5,"السنة "&C$50,'النموذج الشهري'!$C$34:$AL$34)+SUMIF('النموذج الشهري'!$C$5:$AL$5,"السنة "&C$50,'النموذج الشهري'!$C$35:$AL$35)+SUMIF('النموذج الشهري'!$C$5:$AL$5,"السنة "&C$50,'النموذج الشهري'!$C$36:$AL$36)+SUMIF('النموذج الشهري'!$C$5:$AL$5,"السنة "&C$50,'النموذج الشهري'!$C$37:$AL$37) -> 68240 | D18: =SUMIF('النموذج الشهري'!$C$5:$AL$5,"السنة "&D$50,'النموذج الشهري'!$C$34:$AL$34)+SUMIF('النموذج الشهري'!$C$5:$AL$5,"السنة "&D$50,'النموذج الشهري'!$C$35:$AL$35)+SUMIF('النموذج الشهري'!$C$5:$AL$5,"السنة "&D$50,'النموذج الشهري'!$C$36:$AL$36)+SUMIF('النموذج الشهري'!$C$5:$AL$5,"السنة "&D$50,'النموذج الشهري'!$C$37:$AL$37) -> 101170 | E18: =SUMIF('النموذج الشهري'!$C$5:$AL$5,"السنة "&E$50,'النموذج الشهري'!$C$34:$AL$34)+SUMIF('النموذج الشهري'!$C$5:$AL$5,"السنة "&E$50,'النموذج الشهري'!$C$35:$AL$35)+SUMIF('النموذج الشهري'!$C$5:$AL$5,"السنة "&E$50,'النموذج الشهري'!$C$36:$AL$36)+SUMIF('النموذج الشهري'!$C$5:$AL$5,"السنة "&E$50,'النموذج الشهري'!$C$37:$AL$37) -> 132817.5 | F18: =SUM(C18:E18) -> 302227.5
B19: إجمالي المصاريف التشغيلية | C19: =SUMIF('النموذج الشهري'!$C$5:$AL$5,"السنة "&C$50,'النموذج الشهري'!$C$38:$AL$38) -> 260640 | D19: =SUMIF('النموذج الشهري'!$C$5:$AL$5,"السنة "&D$50,'النموذج الشهري'!$C$38:$AL$38) -> 725770 | E19: =SUMIF('النموذج الشهري'!$C$5:$AL$5,"السنة "&E$50,'النموذج الشهري'!$C$38:$AL$38) -> 1427392.5 | F19: =SUM(C19:E19) -> 2413802.5
B20: صافي الربح / الخسارة التشغيلية | C20: =SUMIF('النموذج الشهري'!$C$5:$AL$5,"السنة "&C$50,'النموذج الشهري'!$C$39:$AL$39) -> -259381.28 | D20: =SUMIF('النموذج الشهري'!$C$5:$AL$5,"السنة "&D$50,'النموذج الشهري'!$C$39:$AL$39) -> -674552.48 | E20: =SUMIF('النموذج الشهري'!$C$5:$AL$5,"السنة "&E$50,'النموذج الشهري'!$C$39:$AL$39) -> -1229522.8 | F20: =SUM(C20:E20) -> -2163456.6
B21: النقد والتمويل
B22: التمويل المستلم | C22: =SUMIF('النموذج الشهري'!$C$5:$AL$5,"السنة "&C$50,'النموذج الشهري'!$C$42:$AL$42) -> 1200000 | D22: =SUMIF('النموذج الشهري'!$C$5:$AL$5,"السنة "&D$50,'النموذج الشهري'!$C$42:$AL$42) -> 0 | E22: =SUMIF('النموذج الشهري'!$C$5:$AL$5,"السنة "&E$50,'النموذج الشهري'!$C$42:$AL$42) -> 5000000 | F22: =SUM(C22:E22) -> 6200000
B23: النقد آخر السنة | C23: =INDEX('النموذج الشهري'!$C$45:$AL$45,1,C$50*12) -> 940618.72 | D23: =INDEX('النموذج الشهري'!$C$45:$AL$45,1,D$50*12) -> 266066.24 | E23: =INDEX('النموذج الشهري'!$C$45:$AL$45,1,E$50*12) -> 4036543.4
B24: عدد الفريق آخر السنة | C24: =INDEX(الفريق!$G$23:$AP$23,1,C$50*12) -> 8 | D24: =INDEX(الفريق!$G$23:$AP$23,1,D$50*12) -> 10 | E24: =INDEX(الفريق!$G$23:$AP$23,1,E$50*12) -> 15
B26: المؤشرات الرئيسية
B27: نمو الإيرادات السنوي | D27: =IF(C13>0,D13/C13-1,0) -> 9.9501005 | E27: =IF(D13>0,E13/D13-1,0) -> 2.6752795
B28: هامش الربح الإجمالي | C28: =IF(C13>0,C15/C13,0) -> 0.16163759 | D28: =IF(D13>0,D15/D13,0) -> 0.60063915 | E28: =IF(E13>0,E15/E13,0) -> 0.63137013
B29: تكلفة اكتساب مستخدم (تسويق ÷ تحميلات) | C29: =IF(C8>0,C17/C8,0) -> 1.4882612 | D29: =IF(D8>0,D17/D8,0) -> 1.2921761 | E29: =IF(E8>0,E17/E8,0) -> 1.2431643
B30: تكلفة اكتساب مستخدم نشط | C30: =IF(C8>0,C17/(C8*الافتراضات!$F$10),0) -> 4.2521749 | D30: =IF(D8>0,D17/(D8*الافتراضات!$F$10),0) -> 3.6919317 | E30: =IF(E8>0,E17/(E8*الافتراضات!$F$10),0) -> 3.5518981
B31: متوسط الإيراد الشهري لكل مستخدم نشط (ARPU) | C31: =IFERROR(C13/SUMIF('النموذج الشهري'!$C$5:$AL$5,"السنة "&C$50,'النموذج الشهري'!$C$13:$AL$13),0) -> 0.26590715 | D31: =IFERROR(D13/SUMIF('النموذج الشهري'!$C$5:$AL$5,"السنة "&D$50,'النموذج الشهري'!$C$13:$AL$13),0) -> 0.28 | E31: =IFERROR(E13/SUMIF('النموذج الشهري'!$C$5:$AL$5,"السنة "&E$50,'النموذج الشهري'!$C$13:$AL$13),0) -> 0.28
B32: القيمة الدائمة للمستخدم النشط (LTV) | C32: =IF(الافتراضات!$F$11>0,C31*C28/الافتراضات!$F$11,0) -> 0.53725738 | D32: =IF(الافتراضات!$F$11>0,D31*D28/الافتراضات!$F$11,0) -> 2.102237 | E32: =IF(الافتراضات!$F$11>0,E31*E28/الافتراضات!$F$11,0) -> 2.2097954
B33: نسبة LTV إلى تكلفة الاكتساب (الهدف > 3) | C33: =IF(C30>0,C32/C30,0) -> 0.12634884 | D33: =IF(D30>0,D32/D30,0) -> 0.56941384 | E33: =IF(E30>0,E32/E30,0) -> 0.62214495
B35: فحص كفاية التمويل
B36: أدنى رصيد نقدي خلال 36 شهراً | C36: =MIN('النموذج الشهري'!C45:AL45) -> 11741.056 | D36: =IF(C36<0,"⚠ عجز – يلزم تمويل إضافي أو تقليل المصاريف","✓ التمويل كافٍ") -> ✓ التمويل كافٍ
B37: أعلى حرق شهري | C37: =MAX('النموذج الشهري'!C46:AL46) -> 109984
B38: ملكية المؤسسين بعد Seed و Series A | C38: =الافتراضات!G64 -> 0.576
B40: ملاحظات مهمة:
B41: • كل الأرقام تقديرات لأغراض التخطيط وليست ضماناً. عدّل الخلايا الزرقاء في ورقة الافتراضات وسيتحدث النموذج تلقائياً.
B42: • التطبيقات الاجتماعية عادةً لا تربح في أول 3 سنوات؛ قيمتها عند البيع تُقاس بعدد المستخدمين النشطين ونسبة بقائهم.
B43: • لا تصرف ميزانية إطلاق الرياض إلا بعد تحقيق نسب البقاء المستهدفة في اختبار الكثافة.
C50: 1 | D50: 2 | E50: 3

Sheet الافتراضات
A1: SocialEarth – الافتراضات (كل الأرقام بالدولار الأمريكي)
B2: دليل الألوان: أزرق = مُدخل يمكنك تعديله · أسود = معادلة · أخضر = رابط من ورقة أخرى · أصفر = افتراض رئيسي
B4: السيناريو المختار ← | C4: أساسي | D4: =MATCH(C4,$C$7:$E$7,0) -> 2 | E4: ← اختر من القائمة: متحفظ / أساسي / متفائل
B6: 1) افتراضات السيناريو
B7: البند | C7: متحفظ | D7: أساسي | E7: متفائل | F7: المُفعّل | G7: ملاحظة / المصدر
B8: تكلفة التحميل الواحد (CPI) | C8: 2.5 | D8: 1.5 | E8: 1 | F8: =INDEX(C8:E8,1,$D$4) -> 1.5 | G8: تقدير لإعلانات سناب وتيك توك في السعودية لتطبيقات اجتماعية
B9: نمو عضوي: مستخدمون جدد شهرياً لكل مستخدم نشط | C9: 0.04 | D9: 0.08 | E9: 0.14 | F9: =INDEX(C9:E9,1,$D$4) -> 0.08 | G9: دعوات الأصدقاء + المشاركة على سناب (Creative Kit)
B10: نسبة من يبقى نشطاً بعد الشهر الأول | C10: 0.22 | D10: 0.35 | E10: 0.45 | F10: =INDEX(C10:E10,1,$D$4) -> 0.35 | G10: تقدير؛ معيار التطبيقات الاجتماعية الناجحة 30–45%
B11: نسبة فقدان المستخدمين النشطين شهرياً | C11: 0.12 | D11: 0.08 | E11: 0.05 | F11: =INDEX(C11:E11,1,$D$4) -> 0.08 | G11: تقدير
B12: نسبة المستخدمين الدافعين | C12: 0.015 | D12: 0.025 | E12: 0.04 | F12: =INDEX(C12:E12,1,$D$4) -> 0.025 | G12: معيار ألعاب الجوال 1–5%
B13: متوسط إنفاق الدافع شهرياً (قبل عمولة المتجر) | C13: 5 | D13: 8 | E13: 12 | F13: =INDEX(C13:E13,1,$D$4) -> 8 | G13: تقدير؛ العملات، السفر، السيارات، أثاث البيت
B14: عدد المستخدمين النشطين لكل محل ممول | C14: 4000 | D14: 2500 | E14: 1500 | F14: =INDEX(C14:E14,1,$D$4) -> 2500 | G14: تقدير؛ كثافة المحلات الممولة في الخريطة
B15: اشتراك المحل الممول شهرياً | C15: 100 | D15: 150 | E15: 250 | F15: =INDEX(C15:E15,1,$D$4) -> 150 | G15: تقدير لمقاهٍ ومطاعم الرياض
B16: إيراد الفعاليات والعلامات التجارية لكل مستخدم نشط شهرياً | C16: 0.01 | D16: 0.02 | E16: 0.04 | F16: =INDEX(C16:E16,1,$D$4) -> 0.02 | G16: تقدير
B17: مبلغ جولة Series A | C17: 3000000 | D17: 5000000 | E17: 8000000 | F17: =INDEX(C17:E17,1,$D$4) -> 5000000 | G17: يعتمد على الأرقام المحققة
B18: تقييم ما قبل Series A | C18: 12000000 | D18: 20000000 | E18: 35000000 | F18: =INDEX(C18:E18,1,$D$4) -> 20000000 | G18: تقدير
B20: 2) افتراضات عامة
B21: تاريخ بداية الشهر الأول | C21: 46327 | D21: بداية التأسيس
B22: شهر الإطلاق (اختبار الكثافة) | C22: 8 | D22: بعد 6 أشهر تطوير
B23: شهر بدء المحلات الممولة | C23: 10 | D23: مع إطلاق الرياض
B24: عمولة Apple / Google | C24: 0.3 | D24: 15% لبرنامج الشركات الصغيرة تحت مليون $؛ استخدمنا 30% للتحفظ
B25: خوادم ثابتة شهرياً | C25: 300 | D25: Nakama + قاعدة بيانات
B26: تكلفة الخوادم لكل مستخدم نشط شهرياً | C26: 0.03 | D26: تقدير
B27: رقابة المحتوى بالذكاء الاصطناعي لكل مستخدم نشط | C27: 0.01 | D27: تقدير
B28: أدوات وبرامج لكل عضو فريق شهرياً | C28: 150 | D28: Unity، أدوات AI للبرمجة
B29: أدوات ثابتة شهرياً | C29: 500 | D29: توليد 3D بالذكاء الاصطناعي، تصميم
B30: احتياطي طوارئ (% من المصاريف التشغيلية) | C30: 0.1 | D30: حماية من تقدير التكاليف بأقل من الواقع
B31: زيادة الرواتب السنوية | C31: 0.05 | D31: تقدير
B32: حصة خيارات الموظفين (ESOP) | C32: 0.1 | D32: معيار السوق 10–15%
B34: 3) مراحل المشروع وميزانية التسويق الشهرية
B35: المرحلة | C35: شهر البداية | D35: تسويق شهرياً | E35: الوصف
B36: 0. التأسيس والتطوير | C36: 1 | D36: 300 | E36: الهوية، صفحة الهبوط، قائمة الانتظار
B37: 1أ. اختبار الكثافة | C37: 8 | D37: 10000 | E37: جامعة / حي واحد في الرياض
B38: 1ب. إطلاق الرياض | C38: 10 | D38: 7500 | E38: مؤثرون كبار + إعلانات
B39: 2. التوسع السعودي | C39: 16 | D39: 20000 | E39: جدة والدمام
B40: 3. الخليج | C40: 25 | D40: 50000 | E40: الإمارات، الكويت، قطر...
B42: 4) مصاريف إدارية شهرية
B43: البند | C43: شهر البداية | D43: التكلفة الشهرية
B44: محامٍ (اتفاق شهري) | C44: 1 | D44: 800
B45: محاسب | C45: 1 | D45: 300
...

Sheet الفريق
A1: SocialEarth – خطة الفريق والرواتب الشهرية (تكلفة كاملة بالدولار)
G2: ← أرقام الأشهر (1 = نوفمبر 2026)
A3: الدور | B3: النوع | C3: شهر البداية | D3: شهر النهاية | E3: التكلفة الشهرية | G3: 1 | H3: 2 | I3: 3 | J3: 4 | K3: 5 | L3: 6 | M3: 7 | N3: 8 | O3: 9 | P3: 10 | Q3: 11 | R3: 12 | S3: 13 | T3: 14 | U3: 15 | V3: 16 | W3: 17 | X3: 18 | Y3: 19 | Z3: 20 | AA3: 21 | AB3: 22 | AC3: 23 | AD3: 24 | AE3: 25 | AF3: 26 | AG3: 27 | AH3: 28 | AI3: 29 | AJ3: 30 | AK3: 31 | AL3: 32 | AM3: 33 | AN3: 34 | AO3: 35 | AP3: 36
A4: المؤسس / المدير التنفيذي | B4: كامل | C4: 11 | D4: 36 | E4: 4000 | G4: =IF(AND(G$3>=$C4,G$3<=$D4),$E4*(1+الافتراضات!$C$31)^INT((G$3-1)/12),0) -> 0 | H4: =IF(AND(H$3>=$C4,H$3<=$D4),$E4*(1+الافتراضات!$C$31)^INT((H$3-1)/12),0) -> 0 | I4: =IF(AND(I$3>=$C4,I$3<=$D4),$E4*(1+الافتراضات!$C$31)^INT((I$3-1)/12),0) -> 0 | J4: =IF(AND(J$3>=$C4,J$3<=$D4),$E4*(1+الافتراضات!$C$31)^INT((J$3-1)/12),0) -> 0 | K4: =IF(AND(K$3>=$C4,K$3<=$D4),$E4*(1+الافتراضات!$C$31)^INT((K$3-1)/12),0) -> 0 | L4: =IF(AND(L$3>=$C4,L$3<=$D4),$E4*(1+الافتراضات!$C$31)^INT((L$3-1)/12),0) -> 0 | M4: =IF(AND(M$3>=$C4,M$3<=$D4),$E4*(1+الافتراضات!$C$31)^INT((M$3-1)/12),0) -> 0 | N4: =IF(AND(N$3>=$C4,N$3<=$D4),$E4*(1+الافتراضات!$C$31)^INT((N$3-1)/12),0) -> 0 | ... AP4: =IF(AND(AP$3>=$C4,AP$3<=$D4),$E4*(1+الافتراضات!$C$31)^INT((AP$3-1)/12),0) -> 4410
A5: مطوّر Unity قائد (القائد التقني) | B5: كامل | C5: 1 | D5: 36 | E5: 4500 | G5: =IF(AND(G$3>=$C5,G$3<=$D5),$E5*(1+الافتراضات!$C$31)^INT((G$3-1)/12),0) -> 4500 | H5: =IF(AND(H$3>=$C5,H$3<=$D5),$E5*(1+الافتراضات!$C$31)^INT((H$3-1)/12),0) -> 4500 | I5: =IF(AND(I$3>=$C5,I$3<=$D5),$E5*(1+الافتراضات!$C$31)^INT((I$3-1)/12),0) -> 4500 | J5: =IF(AND(J$3>=$C5,J$3<=$D5),$E5*(1+الافتراضات!$C$31)^INT((J$3-1)/12),0) -> 4500 | K5: =IF(AND(K$3>=$C5,K$3<=$D5),$E5*(1+الافتراضات!$C$31)^INT((K$3-1)/12),0) -> 4500 | L5: =IF(AND(L$3>=$C5,L$3<=$D5),$E5*(1+الافتراضات!$C$31)^INT((L$3-1)/12),0) -> 4500 | M5: =IF(AND(M$3>=$C5,M$3<=$D5),$E5*(1+الافتراضات!$C$31)^INT((M$3-1)/12),0) -> 4500 | N5: =IF(AND(N$3>=$C5,N$3<=$D5),$E5*(1+الافتراضات!$C$31)^INT((N$3-1)/12),0) -> 4500 | ... AP5: =IF(AND(AP$3>=$C5,AP$3<=$D5),$E5*(1+الافتراضات!$C$31)^INT((AP$3-1)/12),0) -> 4961.25
A6: مطوّر خوادم | B6: كامل | C6: 2 | D6: 36 | E6: 4000 | G6: =IF(AND(G$3>=$C6,G$3<=$D6),$E6*(1+الافتراضات!$C$31)^INT((G$3-1)/12),0) -> 0 | H6: =IF(AND(H$3>=$C6,H$3<=$D6),$E6*(1+الافتراضات!$C$31)^INT((H$3-1)/12),0) -> 4000 | I6: =IF(AND(I$3>=$C6,I$3<=$D6),$E6*(1+الافتراضات!$C$31)^INT((I$3-1)/12),0) -> 4000 | J6: =IF(AND(J$3>=$C6,J$3<=$D6),$E6*(1+الافتراضات!$C$31)^INT((J$3-1)/12),0) -> 4000 | K6: =IF(AND(K$3>=$C6,K$3<=$D6),$E6*(1+الافتراضات!$C$31)^INT((K$3-1)/12),0) -> 4000 | L6: =IF(AND(L$3>=$C6,L$3<=$D6),$E6*(1+الافتراضات!$C$31)^INT((L$3-1)/12),0) -> 4000 | M6: =IF(AND(M$3>=$C6,M$3<=$D6),$E6*(1+الافتراضات!$C$31)^INT((M$3-1)/12),0) -> 4000 | N6: =IF(AND(N$3>=$C6,N$3<=$D6),$E6*(1+الافتراضات!$C$31)^INT((N$3-1)/12),0) -> 4000 | ... AP6: =IF(AND(AP$3>=$C6,AP$3<=$D6),$E6*(1+الافتراضات!$C$31)^INT((AP$3-1)/12),0) -> 4410
A7: فنان 3D مع أدوات AI | B7: فريلانسر | C7: 1 | D7: 12 | E7: 2000 | G7: =IF(AND(G$3>=$C7,G$3<=$D7),$E7*(1+الافتراضات!$C$31)^INT((G$3-1)/12),0) -> 2000 | H7: =IF(AND(H$3>=$C7,H$3<=$D7),$E7*(1+الافتراضات!$C$31)^INT((H$3-1)/12),0) -> 2000 | I7: =IF(AND(I$3>=$C7,I$3<=$D7),$E7*(1+الافتراضات!$C$31)^INT((I$3-1)/12),0) -> 2000 | J7: =IF(AND(J$3>=$C7,J$3<=$D7),$E7*(1+الافتراضات!$C$31)^INT((J$3-1)/12),0) -> 2000 | K7: =IF(AND(K$3>=$C7,K$3<=$D7),$E7*(1+الافتراضات!$C$31)^INT((K$3-1)/12),0) -> 2000 | L7: =IF(AND(L$3>=$C7,L$3<=$D7),$E7*(1+الافتراضات!$C$31)^INT((L$3-1)/12),0) -> 2000 | M7: =IF(AND(M$3>=$C7,M$3<=$D7),$E7*(1+الافتراضات!$C$31)^INT((M$3-1)/12),0) -> 2000 | N7: =IF(AND(N$3>=$C7,N$3<=$D7),$E7*(1+الافتراضات!$C$31)^INT((N$3-1)/12),0) -> 2000 | ... AP7: =IF(AND(AP$3>=$C7,AP$3<=$D7),$E7*(1+الافتراضات!$C$31)^INT((AP$3-1)/12),0) -> 0
A8: مدير مجتمع | B8: جزئي | C8: 7 | D8: 10 | E8: 1200 | G8: =IF(AND(G$3>=$C8,G$3<=$D8),$E8*(1+الافتراضات!$C$31)^INT((G$3-1)/12),0) -> 0 | H8: =IF(AND(H$3>=$C8,H$3<=$D8),$E8*(1+الافتراضات!$C$31)^INT((H$3-1)/12),0) -> 0 | I8: =IF(AND(I$3>=$C8,I$3<=$D8),$E8*(1+الافتراضات!$C$31)^INT((I$3-1)/12),0) -> 0 | J8: =IF(AND(J$3>=$C8,J$3<=$D8),$E8*(1+الافتراضات!$C$31)^INT((J$3-1)/12),0) -> 0 | K8: =IF(AND(K$3>=$C8,K$3<=$D8),$E8*(1+الافتراضات!$C$31)^INT((K$3-1)/12),0) -> 0 | L8: =IF(AND(L$3>=$C8,L$3<=$D8),$E8*(1+الافتراضات!$C$31)^INT((L$3-1)/12),0) -> 0 | M8: =IF(AND(M$3>=$C8,M$3<=$D8),$E8*(1+الافتراضات!$C$31)^INT((M$3-1)/12),0) -> 1200 | N8: =IF(AND(N$3>=$C8,N$3<=$D8),$E8*(1+الافتراضات!$C$31)^INT((N$3-1)/12),0) -> 1200 | ... AP8: =IF(AND(AP$3>=$C8,AP$3<=$D8),$E8*(1+الافتراضات!$C$31)^INT((AP$3-1)/12),0) -> 0
A9: مدير مجتمع | B9: كامل | C9: 11 | D9: 36 | E9: 2000 | G9: =IF(AND(G$3>=$C9,G$3<=$D9),$E9*(1+الافتراضات!$C$31)^INT((G$3-1)/12),0) -> 0 | H9: =IF(AND(H$3>=$C9,H$3<=$D9),$E9*(1+الافتراضات!$C$31)^INT((H$3-1)/12),0) -> 0 | I9: =IF(AND(I$3>=$C9,I$3<=$D9),$E9*(1+الافتراضات!$C$31)^INT((I$3-1)/12),0) -> 0 | J9: =IF(AND(J$3>=$C9,J$3<=$D9),$E9*(1+الافتراضات!$C$31)^INT((J$3-1)/12),0) -> 0 | K9: =IF(AND(K$3>=$C9,K$3<=$D9),$E9*(1+الافتراضات!$C$31)^INT((K$3-1)/12),0) -> 0 | L9: =IF(AND(L$3>=$C9,L$3<=$D9),$E9*(1+الافتراضات!$C$31)^INT((L$3-1)/12),0) -> 0 | M9: =IF(AND(M$3>=$C9,M$3<=$D9),$E9*(1+الافتراضات!$C$31)^INT((M$3-1)/12),0) -> 0 | N9: =IF(AND(N$3>=$C9,N$3<=$D9),$E9*(1+الافتراضات!$C$31)^INT((N$3-1)/12),0) -> 0 | ... AP9: =IF(AND(AP$3>=$C9,AP$3<=$D9),$E9*(1+الافتراضات!$C$31)^INT((AP$3-1)/12),0) -> 2205
A10: مطوّر Unity 2 | B10: كامل | C10: 12 | D10: 36 | E10: 4000 | G10: =IF(AND(G$3>=$C10,G$3<=$D10),$E10*(1+الافتراضات!$C$31)^INT((G$3-1)/12),0) -> 0 | H10: =IF(AND(H$3>=$C10,H$3<=$D10),$E10*(1+الافتراضات!$C$31)^INT((H$3-1)/12),0) -> 0 | I10: =IF(AND(I$3>=$C10,I$3<=$D10),$E10*(1+الافتراضات!$C$31)^INT((I$3-1)/12),0) -> 0 | J10: =IF(AND(J$3>=$C10,J$3<=$D10),$E10*(1+الافتراضات!$C$31)^INT((J$3-1)/12),0) -> 0 | K10: =IF(AND(K$3>=$C10,K$3<=$D10),$E10*(1+الافتراضات!$C$31)^INT((K$3-1)/12),0) -> 0 | L10: =IF(AND(L$3>=$C10,L$3<=$D10),$E10*(1+الافتراضات!$C$31)^INT((L$3-1)/12),0) -> 0 | M10: =IF(AND(M$3>=$C10,M$3<=$D10),$E10*(1+الافتراضات!$C$31)^INT((M$3-1)/12),0) -> 0 | N10: =IF(AND(N$3>=$C10,N$3<=$D10),$E10*(1+الافتراضات!$C$31)^INT((N$3-1)/12),0) -> 0 | ... AP10: =IF(AND(AP$3>=$C10,AP$3<=$D10),$E10*(1+الافتراضات!$C$31)^INT((AP$3-1)/12),0) -> 4410
A11: مسؤول الأمان ورقابة المحتوى | B11: كامل | C11: 12 | D11: 36 | E11: 2500 | G11: =IF(AND(G$3>=$C11,G$3<=$D11),$E11*(1+الافتراضات!$C$31)^INT((G$3-1)/12),0) -> 0 | H11: =IF(AND(H$3>=$C11,H$3<=$D11),$E11*(1+الافتراضات!$C$31)^INT((H$3-1)/12),0) -> 0 | I11: =IF(AND(I$3>=$C11,I$3<=$D11),$E11*(1+الافتراضات!$C$31)^INT((I$3-1)/12),0) -> 0 | J11: =IF(AND(J$3>=$C11,J$3<=$D11),$E11*(1+الافتراضات!$C$31)^INT((J$3-1)/12),0) -> 0 | K11: =IF(AND(K$3>=$C11,K$3<=$D11),$E11*(1+الافتراضات!$C$31)^INT((K$3-1)/12),0) -> 0 | L11: =IF(AND(L$3>=$C11,L$3<=$D11),$E11*(1+الافتراضات!$C$31)^INT((L$3-1)/12),0) -> 0 | M11: =IF(AND(M$3>=$C11,M$3<=$D11),$E11*(1+الافتراضات!$C$31)^INT((M$3-1)/12),0) -> 0 | N11: =IF(AND(N$3>=$C11,N$3<=$D11),$E11*(1+الافتراضات!$C$31)^INT((N$3-1)/12),0) -> 0 | ... AP11: =IF(AND(AP$3>=$C11,AP$3<=$D11),$E11*(1+الافتراضات!$C$31)^INT((AP$3-1)/12),0) -> 2756.25
A12: مبيعات الشراكات (المحلات الممولة) | B12: كامل | C12: 12 | D12: 36 | E12: 2500 | G12: =IF(AND(G$3>=$C12,G$3<=$D12),$E12*(1+الافتراضات!$C$31)^INT((G$3-1)/12),0) -> 0 | H12: =IF(AND(H$3>=$C12,H$3<=$D12),$E12*(1+الافتراضات!$C$31)^INT((H$3-1)/12),0) -> 0 | I12: =IF(AND(I$3>=$C12,I$3<=$D12),$E12*(1+الافتراضات!$C$31)^INT((I$3-1)/12),0) -> 0 | J12: =IF(AND(J$3>=$C12,J$3<=$D12),$E12*(1+الافتراضات!$C$31)^INT((J$3-1)/12),0) -> 0 | K12: =IF(AND(K$3>=$C12,K$3<=$D12),$E12*(1+الافتراضات!$C$31)^INT((K$3-1)/12),0) -> 0 | L12: =IF(AND(L$3>=$C12,L$3<=$D12),$E12*(1+الافتراضات!$C$31)^INT((L$3-1)/12),0) -> 0 | M12: =IF(AND(M$3>=$C12,M$3<=$D12),$E12*(1+الافتراضات!$C$31)^INT((M$3-1)/12),0) -> 0 | N12: =IF(AND(N$3>=$C12,N$3<=$D12),$E12*(1+الافتراضات!$C$31)^INT((N$3-1)/12),0) -> 0 | ... AP12: =IF(AND(AP$3>=$C12,AP$3<=$D12),$E12*(1+الافتراضات!$C$31)^INT((AP$3-1)/12),0) -> 2756.25
A13: مطوّر خوادم 2 | B13: كامل | C13: 13 | D13: 36 | E13: 4000 | G13: =IF(AND(G$3>=$C13,G$3<=$D13),$E13*(1+الافتراضات!$C$31)^INT((G$3-1)/12),0) -> 0 | H13: =IF(AND(H$3>=$C13,H$3<=$D13),$E13*(1+الافتراضات!$C$31)^INT((H$3-1)/12),0) -> 0 | I13: =IF(AND(I$3>=$C13,I$3<=$D13),$E13*(1+الافتراضات!$C$31)^INT((I$3-1)/12),0) -> 0 | J13: =IF(AND(J$3>=$C13,J$3<=$D13),$E13*(1+الافتراضات!$C$31)^INT((J$3-1)/12),0) -> 0 | K13: =IF(AND(K$3>=$C13,K$3<=$D13),$E13*(1+الافتراضات!$C$31)^INT((K$3-1)/12),0) -> 0 | L13: =IF(AND(L$3>=$C13,L$3<=$D13),$E13*(1+الافتراضات!$C$31)^INT((L$3-1)/12),0) -> 0 | M13: =IF(AND(M$3>=$C13,M$3<=$D13),$E13*(1+الافتراضات!$C$31)^INT((M$3-1)/12),0) -> 0 | N13: =IF(AND(N$3>=$C13,N$3<=$D13),$E13*(1+الافتراضات!$C$31)^INT((N$3-1)/12),0) -> 0 | ... AP13: =IF(AND(AP$3>=$C13,AP$3<=$D13),$E13*(1+الافتراضات!$C$31)^INT((AP$3-1)/12),0) -> 4410
A14: مصمم منتج UX | B14: كامل | C14: 13 | D14: 36 | E14: 3000 | G14: =IF(AND(G$3>=$C14,G$3<=$D14),$E14*(1+الافتراضات!$C$31)^INT((G$3-1)/12),0) -> 0 | H14: =IF(AND(H$3>=$C14,H$3<=$D14),$E14*(1+الافتراضات!$C$31)^INT((H$3-1)/12),0) -> 0 | I14: =IF(AND(I$3>=$C14,I$3<=$D14),$E14*(1+الافتراضات!$C$31)^INT((I$3-1)/12),0) -> 0 | J14: =IF(AND(J$3>=$C14,J$3<=$D14),$E14*(1+الافتراضات!$C$31)^INT((J$3-1)/12),0) -> 0 | K14: =IF(AND(K$3>=$C14,K$3<=$D14),$E14*(1+الافتراضات!$C$31)^INT((K$3-1)/12),0) -> 0 | L14: =IF(AND(L$3>=$C14,L$3<=$D14),$E14*(1+الافتراضات!$C$31)^INT((L$3-1)/12),0) -> 0 | M14: =IF(AND(M$3>=$C14,M$3<=$D14),$E14*(1+الافتراضات!$C$31)^INT((M$3-1)/12),0) -> 0 | N14: =IF(AND(N$3>=$C14,N$3<=$D14),$E14*(1+الافتراضات!$C$31)^INT((N$3-1)/12),0) -> 0 | ... AP14: =IF(AND(AP$3>=$C14,AP$3<=$D14),$E14*(1+الافتراضات!$C$31)^INT((AP$3-1)/12),0) -> 3307.5
A15: فنان 3D | B15: كامل | C15: 13 | D15: 36 | E15: 3000 | G15: =IF(AND(G$3>=$C15,G$3<=$D15),$E15*(1+الافتراضات!$C$31)^INT((G$3-1)/12),0) -> 0 | H15: =IF(AND(H$3>=$C15,H$3<=$D15),$E15*(1+الافتراضات!$C$31)^INT((H$3-1)/12),0) -> 0 | I15: =IF(AND(I$3>=$C15,I$3<=$D15),$E15*(1+الافتراضات!$C$31)^INT((I$3-1)/12),0) -> 0 | J15: =IF(AND(J$3>=$C15,J$3<=$D15),$E15*(1+الافتراضات!$C$31)^INT((J$3-1)/12),0) -> 0 | K15: =IF(AND(K$3>=$C15,K$3<=$D15),$E15*(1+الافتراضات!$C$31)^INT((K$3-1)/12),0) -> 0 | L15: =IF(AND(L$3>=$C15,L$3<=$D15),$E15*(1+الافتراضات!$C$31)^INT((L$3-1)/12),0) -> 0 | M15: =IF(AND(M$3>=$C15,M$3<=$D15),$E15*(1+الافتراضات!$C$31)^INT((M$3-1)/12),0) -> 0 | N15: =IF(AND(N$3>=$C15,N$3<=$D15),$E15*(1+الافتراضات!$C$31)^INT((N$3-1)/12),0) -> 0 | ... AP15: =IF(AND(AP$3>=$C15,AP$3<=$D15),$E15*(1+الافتراضات!$C$31)^INT((AP$3-1)/12),0) -> 3307.5
... A20: مدير عمليات ومالية | B20: كامل | C20: 25 | D20: 36 | E20: 4000 | G20: =IF(AND(G$3>=$C20,G$3<=$D20),$E20*(1+الافتراضات!$C$31)^INT((G$3-1)/12),0) -> 0 | H20: =IF(AND(H$3>=$C20,H$3<=$D20),$E20*(1+الافتراضات!$C$31)^INT((H$3-1)/12),0) -> 0 | I20: =IF(AND(I$3>=$C20,I$3<=$D20),$E20*(1+الافتراضات!$C$31)^INT((I$3-1)/12),0) -> 0 | J20: =IF(AND(J$3>=$C20,J$3<=$D20),$E20*(1+الافتراضات!$C$31)^INT((J$3-1)/12),0) -> 0 | K20: =IF(AND(K$3>=$C20,K$3<=$D20),$E20*(1+الافتراضات!$C$31)^INT((K$3-1)/12),0) -> 0 | L20: =IF(AND(L$3>=$C20,L$3<=$D20),$E20*(1+الافتراضات!$C$31)^INT((L$3-1)/12),0) -> 0 | M20: =IF(AND(M$3>=$C20,M$3<=$D20),$E20*(1+الافتراضات!$C$31)^INT((M$3-1)/12),0) -> 0 | N20: =IF(AND(N$3>=$C20,N$3<=$D20),$E20*(1+الافتراضات!$C$31)^INT((N$3-1)/12),0) -> 0 | ... AP20: =IF(AND(AP$3>=$C20,AP$3<=$D20),$E20*(1+الافتراضات!$C$31)^INT((AP$3-1)/12),0) -> 4410
A22: إجمالي الرواتب | G22: =SUM(G4:G20) -> 6500 | H22: =SUM(H4:H20) -> 10500 | I22: =SUM(I4:I20) -> 10500 | J22: =SUM(J4:J20) -> 10500 | K22: =SUM(K4:K20) -> 10500 | L22: =SUM(L4:L20) -> 10500 | M22: =SUM(M4:M20) -> 11700 | N22: =SUM(N4:N20) -> 11700 | ... AP22: =SUM(AP4:AP20) -> 57881.25
A23: عدد أعضاء الفريق | G23: =COUNTIF(G4:G20,">0") -> 2 | H23: =COUNTIF(H4:H20,">0") -> 3 | I23: =COUNTIF(I4:I20,">0") -> 3 | J23: =COUNTIF(J4:J20,">0") -> 3 | K23: =COUNTIF(K4:K20,">0") -> 3 | L23: =COUNTIF(L4:L20,">0") -> 3 | M23: =COUNTIF(M4:M20,">0") -> 4 | N23: =COUNTIF(N4:N20,">0") -> 4 | ... AP23: =COUNTIF(AP4:AP20,">0") -> 15
A25: ملاحظة: الرواتب تقديرية لتوظيف عن بُعد من المنطقة (مصر، الأردن، العراق) وتشمل التكلفة الكاملة. عدّل الأرقام الزرقاء.

Sheet النموذج الشهري
A1: SocialEarth – النموذج الشهري (36 شهراً)
A3: رقم الشهر | C3: 1 | D3: 2 | E3: 3 | F3: 4 | G3: 5 | H3: 6 | I3: 7 | J3: 8 | K3: 9 | L3: 10 | M3: 11 | N3: 12 | O3: 13 | P3: 14 | Q3: 15 | R3: 16 | S3: 17 | T3: 18 | U3: 19 | V3: 20 | W3: 21 | X3: 22 | Y3: 23 | Z3: 24 | AA3: 25 | AB3: 26 | AC3: 27 | AD3: 28 | AE3: 29 | AF3: 30 | AG3: 31 | AH3: 32 | AI3: 33 | AJ3: 34 | AK3: 35 | AL3: 36
A4: التاريخ | C4: =EDATE(الافتراضات!$C$21,C3-1) -> 46327 | D4: =EDATE(الافتراضات!$C$21,D3-1) -> 46357 | E4: =EDATE(الافتراضات!$C$21,E3-1) -> 46388 | F4: =EDATE(الافتراضات!$C$21,F3-1) -> 46419 | G4: =EDATE(الافتراضات!$C$21,G3-1) -> 46447 | H4: =EDATE(الافتراضات!$C$21,H3-1) -> 46478 | I4: =EDATE(الافتراضات!$C$21,I3-1) -> 46508 | J4: =EDATE(الافتراضات!$C$21,J3-1) -> 46539 | ... AL4: =EDATE(الافتراضات!$C$21,AL3-1) -> 47392
A5: السنة | C5: ="السنة "&INT((C3-1)/12)+1 -> السنة 1 | D5: ="السنة "&INT((D3-1)/12)+1 -> السنة 1 | E5: ="السنة "&INT((E3-1)/12)+1 -> السنة 1 | F5: ="السنة "&INT((F3-1)/12)+1 -> السنة 1 | G5: ="السنة "&INT((G3-1)/12)+1 -> السنة 1 | H5: ="السنة "&INT((H3-1)/12)+1 -> السنة 1 | I5: ="السنة "&INT((I3-1)/12)+1 -> السنة 1 | J5: ="السنة "&INT((J3-1)/12)+1 -> السنة 1 | ... AL5: ="السنة "&INT((AL3-1)/12)+1 -> السنة 3
A6: المرحلة | C6: =INDEX(الافتراضات!$B$36:$B$40,MATCH(C$3,الافتراضات!$C$36:$C$40,1)) -> 0. التأسيس والتطوير | D6: =INDEX(الافتراضات!$B$36:$B$40,MATCH(D$3,الافتراضات!$C$36:$C$40,1)) -> 0. التأسيس والتطوير | E6: =INDEX(الافتراضات!$B$36:$B$40,MATCH(E$3,الافتراضات!$C$36:$C$40,1)) -> 0. التأسيس والتطوير | F6: =INDEX(الافتراضات!$B$36:$B$40,MATCH(F$3,الافتراضات!$C$36:$C$40,1)) -> 0. التأسيس والتطوير | G6: =INDEX(الافتراضات!$B$36:$B$40,MATCH(G$3,الافتراضات!$C$36:$C$40,1)) -> 0. التأسيس والتطوير | H6: =INDEX(الافتراضات!$B$36:$B$40,MATCH(H$3,الافتراضات!$C$36:$C$40,1)) -> 0. التأسيس والتطوير | I6: =INDEX(الافتراضات!$B$36:$B$40,MATCH(I$3,الافتراضات!$C$36:$C$40,1)) -> 0. التأسيس والتطوير | J6: =INDEX(الافتراضات!$B$36:$B$40,MATCH(J$3,الافتراضات!$C$36:$C$40,1)) -> 1أ. اختبار الكثافة | ... AL6: =INDEX(الافتراضات!$B$36:$B$40,MATCH(AL$3,الافتراضات!$C$36:$C$40,1)) -> 3. الخليج
A8: المستخدمون
A9: ميزانية التسويق | B9: $ | C9: =INDEX(الافتراضات!$D$36:$D$40,MATCH(C$3,الافتراضات!$C$36:$C$40,1)) -> 300 | D9: =INDEX(الافتراضات!$D$36:$D$40,MATCH(D$3,الافتراضات!$C$36:$C$40,1)) -> 300 | E9: =INDEX(الافتراضات!$D$36:$D$40,MATCH(E$3,الافتراضات!$C$36:$C$40,1)) -> 300 | F9: =INDEX(الافتراضات!$D$36:$D$40,MATCH(F$3,الافتراضات!$C$36:$C$40,1)) -> 300 | G9: =INDEX(الافتراضات!$D$36:$D$40,MATCH(G$3,الافتراضات!$C$36:$C$40,1)) -> 300 | H9: =INDEX(الافتراضات!$D$36:$D$40,MATCH(H$3,الافتراضات!$C$36:$C$40,1)) -> 300 | I9: =INDEX(الافتراضات!$D$36:$D$40,MATCH(I$3,الافتراضات!$C$36:$C$40,1)) -> 300 | J9: =INDEX(الافتراضات!$D$36:$D$40,MATCH(J$3,الافتراضات!$C$36:$C$40,1)) -> 10000 | ... AL9: =INDEX(الافتراضات!$D$36:$D$40,MATCH(AL$3,الافتراضات!$C$36:$C$40,1)) -> 50000
A10: تحميلات مدفوعة | B10: مستخدم | C10: =IF(C$3>=الافتراضات!$C$22,C9/الافتراضات!$F$8,0) -> 0 | D10: =IF(D$3>=الافتراضات!$C$22,D9/الافتراضات!$F$8,0) -> 0 | E10: =IF(E$3>=الافتراضات!$C$22,E9/الافتراضات!$F$8,0) -> 0 | F10: =IF(F$3>=الافتراضات!$C$22,F9/الافتراضات!$F$8,0) -> 0 | G10: =IF(G$3>=الافتراضات!$C$22,G9/الافتراضات!$F$8,0) -> 0 | H10: =IF(H$3>=الافتراضات!$C$22,H9/الافتراضات!$F$8,0) -> 0 | I10: =IF(I$3>=الافتراضات!$C$22,I9/الافتراضات!$F$8,0) -> 0 | J10: =IF(J$3>=الافتراضات!$C$22,J9/الافتراضات!$F$8,0) -> 6666.6667 | ... AL10: =IF(AL$3>=الافتراضات!$C$22,AL9/الافتراضات!$F$8,0) -> 33333.333
A11: تحميلات عضوية (دعوات ومشاركة) | B11: مستخدم | C11: =IF(C$3>=الافتراضات!$C$22,الافتراضات!$F$9*0,0) -> 0 | D11: =IF(D$3>=الافتراضات!$C$22,الافتراضات!$F$9*C13,0) -> 0 | E11: =IF(E$3>=الافتراضات!$C$22,الافتراضات!$F$9*D13,0) -> 0 | F11: =IF(F$3>=الافتراضات!$C$22,الافتراضات!$F$9*E13,0) -> 0 | G11: =IF(G$3>=الافتراضات!$C$22,الافتراضات!$F$9*F13,0) -> 0 | H11: =IF(H$3>=الافتراضات!$C$22,الافتراضات!$F$9*G13,0) -> 0 | I11: =IF(I$3>=الافتراضات!$C$22,الافتراضات!$F$9*H13,0) -> 0 | J11: =IF(J$3>=الافتراضات!$C$22,الافتراضات!$F$9*I13,0) -> 0 | K11: =IF(K$3>=الافتراضات!$C$22,الافتراضات!$F$9*J13,0) -> 186.66667 | ... AL11: =IF(AL$3>=الافتراضات!$C$22,الافتراضات!$F$9*AK13,0) -> 9840.4171
A12: إجمالي التحميلات الجديدة | B12: مستخدم | C12: =C10+C11 -> 0 | D12: =D10+D11 -> 0 | E12: =E10+E11 -> 0 | F12: =F10+F11 -> 0 | G12: =G10+G11 -> 0 | H12: =H10+H11 -> 0 | I12: =I10+I11 -> 0 | J12: =J10+J11 -> 6666.6667 | ... AL12: =AL10+AL11 -> 43173.75
A13: المستخدمون النشطون شهرياً (MAU) | B13: مستخدم | C13: =0*(1-الافتراضات!$F$11)+C12*الافتراضات!$F$10 -> 0 | D13: =C13*(1-الافتراضات!$F$11)+D12*الافتراضات!$F$10 -> 0 | E13: =D13*(1-الافتراضات!$F$11)+E12*الافتراضات!$F$10 -> 0 | F13: =E13*(1-الافتراضات!$F$11)+F12*الافتراضات!$F$10 -> 0 | G13: =F13*(1-الافتراضات!$F$11)+G12*الافتراضات!$F$10 -> 0 | H13: =G13*(1-الافتراضات!$F$11)+H12*الافتراضات!$F$10 -> 0 | I13: =H13*(1-الافتراضات!$F$11)+I12*الافتراضات!$F$10 -> 0 | J13: =I13*(1-الافتراضات!$F$11)+J12*الافتراضات!$F$10 -> 2333.3333 | K13: =J13*(1-الافتراضات!$F$11)+K12*الافتراضات!$F$10 -> 4545.3333 | ... AL13: =AK13*(1-الافتراضات!$F$11)+AL12*الافتراضات!$F$10 -> 128275.61
A14: المستخدمون الدافعون | B14: مستخدم | C14: =C13*الافتراضات!$F$12 -> 0 | D14: =D13*الافتراضات!$F$12 -> 0 | E14: =E13*الافتراضات!$F$12 -> 0 | F14: =F13*الافتراضات!$F$12 -> 0 | G14: =G13*الافتراضات!$F$12 -> 0 | H14: =H13*الافتراضات!$F$12 -> 0 | I14: =I13*الافتراضات!$F$12 -> 0 | J14: =J13*الافتراضات!$F$12 -> 58.333333 | ... AL14: =AL13*الافتراضات!$F$12 -> 3206.8902
A16: الإيرادات
A17: مشتريات داخل التطبيق (إجمالي) | B17: $ | C17: =C14*الافتراضات!$F$13 -> 0 | D17: =D14*الافتراضات!$F$13 -> 0 | E17: =E14*الافتراضات!$F$13 -> 0 | F17: =F14*الافتراضات!$F$13 -> 0 | G17: =G14*الافتراضات!$F$13 -> 0 | H17: =H14*الافتراضات!$F$13 -> 0 | I17: =I14*الافتراضات!$F$13 -> 0 | J17: =J14*الافتراضات!$F$13 -> 466.66667 | ... AL17: =AL14*الافتراضات!$F$13 -> 25655.122
A18: عدد المحلات الممولة | B18: محل | C18: =IF(C$3>=الافتراضات!$C$23,C13/الافتراضات!$F$14,0) -> 0 | D18: =IF(D$3>=الافتراضات!$C$23,D13/الافتراضات!$F$14,0) -> 0 | E18: =IF(E$3>=الافتراضات!$C$23,E13/الافتراضات!$F$14,0) -> 0 | F18: =IF(F$3>=الافتراضات!$C$23,F13/الافتراضات!$F$14,0) -> 0 | G18: =IF(G$3>=الافتراضات!$C$23,G13/الافتراضات!$F$14,0) -> 0 | H18: =IF(H$3>=الافتراضات!$C$23,H13/الافتراضات!$F$14,0) -> 0 | I18: =IF(I$3>=الافتراضات!$C$23,I13/الافتراضات!$F$14,0) -> 0 | J18: =IF(J$3>=الافتراضات!$C$23,J13/الافتراضات!$F$14,0) -> 0 | ... AL18: =IF(AL$3>=الافتراضات!$C$23,AL13/الافتراضات!$F$14,0) -> 51.310244
A19: إيراد المحلات الممولة | B19: $ | C19: =C18*الافتراضات!$F$15 -> 0 | D19: =D18*الافتراضات!$F$15 -> 0 | E19: =E18*الافتراضات!$F$15 -> 0 | F19: =F18*الافتراضات!$F$15 -> 0 | G19: =G18*الافتراضات!$F$15 -> 0 | H19: =H18*الافتراضات!$F$15 -> 0 | I19: =I18*الافتراضات!$F$15 -> 0 | J19: =J18*الافتراضات!$F$15 -> 0 | ... AL19: =AL18*الافتراضات!$F$15 -> 7696.5366
A20: إيراد الفعاليات والعلامات التجارية | B20: $ | C20: =C13*الافتراضات!$F$16 -> 0 | D20: =D13*الافتراضات!$F$16 -> 0 | E20: =E13*الافتراضات!$F$16 -> 0 | F20: =F13*الافتراضات!$F$16 -> 0 | G20: =G13*الافتراضات!$F$16 -> 0 | H20: =H13*الافتراضات!$F$16 -> 0 | I20: =I13*الافتراضات!$F$16 -> 0 | J20: =J13*الافتراضات!$F$16 -> 46.666667 | ... AL20: =AL13*الافتراضات!$F$16 -> 2565.5122
A21: إجمالي الإيرادات | B21: $ | C21: =C17+C19+C20 -> 0 | D21: =D17+D19+D20 -> 0 | E21: =E17+E19+E20 -> 0 | F21: =F17+F19+F20 -> 0 | G21: =G17+G19+G20 -> 0 | H21: =H17+H19+H20 -> 0 | I21: =I17+I19+I20 -> 0 | J21: =J17+J19+J20 -> 513.33333 | ... AL21: =AL17+AL19+AL20 -> 35917.171
A23: تكلفة الإيرادات
A24: عمولة Apple / Google | B24: $ | C24: =C17*الافتراضات!$C$24 -> 0 | D24: =D17*الافتراضات!$C$24 -> 0 | E24: =E17*الافتراضات!$C$24 -> 0 | F24: =F17*الافتراضات!$C$24 -> 0 | G24: =G17*الافتراضات!$C$24 -> 0 | H24: =H17*الافتراضات!$C$24 -> 0 | I24: =I17*الافتراضات!$C$24 -> 0 | J24: =J17*الافتراضات!$C$24 -> 140 | ... AL24: =AL17*الافتراضات!$C$24 -> 7696.5366
A25: الخوادم | B25: $ | C25: =الافتراضات!$C$25+C13*الافتراضات!$C$26 -> 300 | D25: =الافتراضات!$C$25+D13*الافتراضات!$C$26 -> 300 | E25: =الافتراضات!$C$25+E13*الافتراضات!$C$26 -> 300 | F25: =الافتراضات!$C$25+F13*الافتراضات!$C$26 -> 300 | G25: =الافتراضات!$C$25+G13*الافتراضات!$C$26 -> 300 | H25: =الافتراضات!$C$25+H13*الافتراضات!$C$26 -> 300 | I25: =الافتراضات!$C$25+I13*الافتراضات!$C$26 -> 300 | J25: =الافتراضات!$C$25+J13*الافتراضات!$C$26 -> 370 | ... AL25: =الافتراضات!$C$25+AL13*الافتراضات!$C$26 -> 4148.2683
A26: رقابة المحتوى بالذكاء الاصطناعي | B26: $ | C26: =C13*الافتراضات!$C$27 -> 0 | D26: =D13*الافتراضات!$C$27 -> 0 | E26: =E13*الافتراضات!$C$27 -> 0 | F26: =F13*الافتراضات!$C$27 -> 0 | G26: =G13*الافتراضات!$C$27 -> 0 | H26: =H13*الافتراضات!$C$27 -> 0 | I26: =I13*الافتراضات!$C$27 -> 0 | J26: =J13*الافتراضات!$C$27 -> 23.333333 | ... AL26: =AL13*الافتراضات!$C$27 -> 1282.7561
A27: إجمالي تكلفة الإيرادات | B27: $ | C27: =C24+C25+C26 -> 300 | D27: =D24+D25+D26 -> 300 | E27: =E24+E25+E26 -> 300 | F27: =F24+F25+F26 -> 300 | G27: =G24+G25+G26 -> 300 | H27: =H24+H25+H26 -> 300 | I27: =I24+I25+I26 -> 300 | J27: =J24+J25+J26 -> 533.33333 | ... AL27: =AL24+AL25+AL26 -> 13127.561
A28: إجمالي الربح | B28: $ | C28: =C21-C27 -> -300 | D28: =D21-D27 -> -300 | E28: =E21-E27 -> -300 | F28: =F21-F27 -> -300 | G28: =G21-G27 -> -300 | H28: =H21-H27 -> -300 | I28: =I21-I27 -> -300 | J28: =J21-J27 -> -20 | ... AL28: =AL21-AL27 -> 22789.61
A29: هامش الربح الإجمالي | B29: % | C29: =IF(C21>0,C28/C21,0) -> 0 | D29: =IF(D21>0,D28/D21,0) -> 0 | E29: =IF(E21>0,E28/E21,0) -> 0 | F29: =IF(F21>0,F28/F21,0) -> 0 | G29: =IF(G21>0,G28/G21,0) -> 0 | H29: =IF(H21>0,H28/H21,0) -> 0 | I29: =IF(I21>0,I28/I21,0) -> 0 | J29: =IF(J21>0,J28/J21,0) -> -0.038961039 | ... AL29: =IF(AL21>0,AL28/AL21,0) -> 0.63450459
A31: المصاريف التشغيلية
A32: الرواتب | B32: $ | C32: =الفريق!G22 -> 6500 | D32: =الفريق!H22 -> 10500 | E32: =الفريق!I22 -> 10500 | F32: =الفريق!J22 -> 10500 | G32: =الفريق!K22 -> 10500 | H32: =الفريق!L22 -> 10500 | I32: =الفريق!M22 -> 11700 | J32: =الفريق!N22 -> 11700 | ... AL32: =الفريق!AP22 -> 57881.25
A33: التسويق | B33: $ | C33: =C9 -> 300 | D33: =D9 -> 300 | E33: =E9 -> 300 | F33: =F9 -> 300 | G33: =G9 -> 300 | H33: =H9 -> 300 | I33: =I9 -> 300 | J33: =J9 -> 10000 | ... AL33: =AL9 -> 50000
A34: الأدوات والبرامج | B34: $ | C34: =الافتراضات!$C$29+الفريق!G23*الافتراضات!$C$28 -> 800 | D34: =الافتراضات!$C$29+الفريق!H23*الافتراضات!$C$28 -> 950 | E34: =الافتراضات!$C$29+الفريق!I23*الافتراضات!$C$28 -> 950 | F34: =الافتراضات!$C$29+الفريق!J23*الافتراضات!$C$28 -> 950 | G34: =الافتراضات!$C$29+الفريق!K23*الافتراضات!$C$28 -> 950 | H34: =الافتراضات!$C$29+الفريق!L23*الافتراضات!$C$28 -> 950 | I34: =الافتراضات!$C$29+الفريق!M23*الافتراضات!$C$28 -> 1100 | J34: =الافتراضات!$C$29+الفريق!N23*الافتراضات!$C$28 -> 1100 | ... AL34: =الافتراضات!$C$29+الفريق!AP23*الافتراضات!$C$28 -> 2750
A35: مصاريف إدارية | B35: $ | C35: =SUMIF(الافتراضات!$C$44:$C$48,"<="&C$3,الافتراضات!$D$44:$D$48) -> 1150 | D35: =SUMIF(الافتراضات!$C$44:$C$48,"<="&D$3,الافتراضات!$D$44:$D$48) -> 1150 | E35: =SUMIF(الافتراضات!$C$44:$C$48,"<="&E$3,الافتراضات!$D$44:$D$48) -> 1150 | F35: =SUMIF(الافتراضات!$C$44:$C$48,"<="&F$3,الافتراضات!$D$44:$D$48) -> 1150 | G35: =SUMIF(الافتراضات!$C$44:$C$48,"<="&G$3,الافتراضات!$D$44:$D$48) -> 1150 | H35: =SUMIF(الافتراضات!$C$44:$C$48,"<="&H$3,الافتراضات!$D$44:$D$48) -> 1150 | I35: =SUMIF(الافتراضات!$C$44:$C$48,"<="&I$3,الافتراضات!$D$44:$D$48) -> 1150 | J35: =SUMIF(الافتراضات!$C$44:$C$48,"<="&J$3,الافتراضات!$D$44:$D$48) -> 1150 | ... AL35: =SUMIF(الافتراضات!$C$44:$C$48,"<="&AL$3,الافتراضات!$D$44:$D$48) -> 2050
A36: تكاليف لمرة واحدة | B36: $ | C36: =SUMIF(الافتراضات!$C$52:$C$57,C$3,الافتراضات!$D$52:$D$57) -> 14000 | D36: =SUMIF(الافتراضات!$C$52:$C$57,D$3,الافتراضات!$D$52:$D$57) -> 0 | E36: =SUMIF(الافتراضات!$C$52:$C$57,E$3,الافتراضات!$D$52:$D$57) -> 0 | F36: =SUMIF(الافتراضات!$C$52:$C$57,F$3,الافتراضات!$D$52:$D$57) -> 0 | G36: =SUMIF(الافتراضات!$C$52:$C$57,G$3,الافتراضات!$D$52:$D$57) -> 0 | H36: =SUMIF(الافتراضات!$C$52:$C$57,H$3,الافتراضات!$D$52:$D$57) -> 0 | I36: =SUMIF(الافتراضات!$C$52:$C$57,I$3,الافتراضات!$D$52:$D$57) -> 2000 | J36: =SUMIF(الافتراضات!$C$52:$C$57,J$3,الافتراضات!$D$52:$D$57) -> 0 | ... AL36: =SUMIF(الافتراضات!$C$52:$C$57,AL$3,الافتراضات!$D$52:$D$57) -> 0
A37: احتياطي طوارئ | B37: $ | C37: =(C32+C34+C35+C36)*الافتراضات!$C$30 -> 2245 | D37: =(D32+D34+D35+D36)*الافتراضات!$C$30 -> 1260 | E37: =(E32+E34+E35+E36)*الافتراضات!$C$30 -> 1260 | F37: =(F32+F34+F35+F36)*الافتراضات!$C$30 -> 1260 | G37: =(G32+G34+G35+G36)*الافتراضات!$C$30 -> 1260 | H37: =(H32+H34+H35+H36)*الافتراضات!$C$30 -> 1260 | I37: =(I32+I34+I35+I36)*الافتراضات!$C$30 -> 1595 | J37: =(J32+J34+J35+J36)*الافتراضات!$C$30 -> 1395 | ... AL37: =(AL32+AL34+AL35+AL36)*الافتراضات!$C$30 -> 6268.125
A38: إجمالي المصاريف التشغيلية | B38: $ | C38: =SUM(C32:C37) -> 24995 | D38: =SUM(D32:D37) -> 14160 | E38: =SUM(E32:E37) -> 14160 | F38: =SUM(F32:F37) -> 14160 | G38: =SUM(G32:G37) -> 14160 | H38: =SUM(H32:H37) -> 14160 | I38: =SUM(I32:I37) -> 17845 | J38: =SUM(J32:J37) -> 25345 | ... AL38: =SUM(AL32:AL37) -> 118949.38
A39: صافي الربح / الخسارة التشغيلية | B39: $ | C39: =C28-C38 -> -25295 | D39: =D28-D38 -> -14460 | E39: =E28-E38 -> -14460 | F39: =F28-F38 -> -14460 | G39: =G28-G38 -> -14460 | H39: =H28-H38 -> -14460 | I39: =I28-I38 -> -18145 | J39: =J28-J38 -> -25365 | ... AL39: =AL28-AL38 -> -96159.765
A41: النقد
A42: التمويل المستلم | B42: $ | C42: =SUMIF(الافتراضات!$C$61:$C$63,C$3,الافتراضات!$D$61:$D$63) -> 200000 | D42: =SUMIF(الافتراضات!$C$61:$C$63,D$3,الافتراضات!$D$61:$D$63) -> 0 | E42: =SUMIF(الافتراضات!$C$61:$C$63,E$3,الافتراضات!$D$61:$D$63) -> 0 | F42: =SUMIF(الافتراضات!$C$61:$C$63,F$3,الافتراضات!$D$61:$D$63) -> 0 | G42: =SUMIF(الافتراضات!$C$61:$C$63,G$3,الافتراضات!$D$61:$D$63) -> 0 | H42: =SUMIF(الافتراضات!$C$61:$C$63,H$3,الافتراضات!$D$61:$D$63) -> 0 | I42: =SUMIF(الافتراضات!$C$61:$C$63,I$3,الافتراضات!$D$61:$D$63) -> 0 | J42: =SUMIF(الافتراضات!$C$61:$C$63,J$3,الافتراضات!$D$61:$D$63) -> 0 | ... AL42: =SUMIF(الافتراضات!$C$61:$C$63,AL$3,الافتراضات!$D$61:$D$63) -> 0
A43: صافي التدفق النقدي | B43: $ | C43: =C39+C42 -> 174705 | D43: =D39+D42 -> -14460 | E43: =E39+E42 -> -14460 | F43: =F39+F42 -> -14460 | G43: =G39+G42 -> -14460 | H43: =H39+H42 -> -14460 | I43: =I39+I42 -> -18145 | J43: =J39+J42 -> -25365 | ... AL43: =AL39+AL42 -> -96159.765
A44: النقد أول الشهر | B44: $ | C44: 0 | D44: =C45 -> 174705 | E44: =D45 -> 160245 | F44: =E45 -> 145785 | G44: =F45 -> 131325 | H44: =G45 -> 116865 | I44: =H45 -> 102405 | J44: =I45 -> 84260 | K44: =J45 -> 58895 | ... AL44: =AK45 -> 4132703.2
A45: النقد آخر الشهر | B45: $ | C45: =C44+C43 -> 174705 | D45: =D44+D43 -> 160245 | E45: =E44+E43 -> 145785 | F45: =F44+F43 -> 131325 | G45: =G44+G43 -> 116865 | H45: =H44+H43 -> 102405 | I45: =I44+I43 -> 84260 | J45: =J44+J43 -> 58895 | ... AL45: =AL44+AL43 -> 4036543.4
A46: الحرق الشهري | B46: $ | C46: =MAX(0,-C39) -> 25295 | D46: =MAX(0,-D39) -> 14460 | E46: =MAX(0,-E39) -> 14460 | F46: =MAX(0,-F39) -> 14460 | G46: =MAX(0,-G39) -> 14460 | H46: =MAX(0,-H39) -> 14460 | I46: =MAX(0,-I39) -> 18145 | J46: =MAX(0,-J39) -> 25365 | ... AL46: =MAX(0,-AL39) -> 96159.765
...
